Workbook
Name bookmark10: 'PL01'!$A$1
Name bookmark13: 'PL02'!$A$1

Sheet PL01
A1: BIỂU SỐ 01
A2: DANH MỤC NGUỒN DỮ LIỆU PHỤC VỤ HOẠT ĐỘNG KIỂM TOÁN
A3: (Kèm theo Công văn số /KV XII - TH ngày tháng 9 năm 2026 của KTNN khu vực XII)
A4: Đơn vị báo cáo: KTNN khu vực XII
A5: Người lập biểu: Nguyễn Đức Đình Huấn - Điện thoại: 0798157333 - Thư điện tử: huanndd@sav.gov.vn
A7: STT | B7: Mã nguồn | C7: Lĩnh vực kiểm toán | D7: Giai đoạn, nhiệm vụ sử dụng dữ liệu | E7: Nhóm dữ liệu | F7: Tên dữ liệu chi tiết cần khai thác | G7: Nội dung, chỉ tiêu chủ yếu cần khai thác | H7: Cơ quan, tổ chức quản lý, lưu giữ | I7: Loại nguồn | J7: Hình thức dữ liệu hiện có | K7: Mục đích sử dụng cụ thể trong hoạt động kiểm toán | L7: Mức độ sử dụng
A8: 1 | B8: 2 | C8: 3 | D8: 4 | E8: 5 | F8: 6 | G8: 7 | H8: 8 | I8: 9 | J8: 10 | K8: 11 | L8: 12
A9: 1 | B9: NS-04 | C9: 2 , 3 | D9: A1, A2 | E9: Chấp hành ngân sách nhà nước, Quyết toán ngân sách nhà nước | F9: Báo cáo về kê khai thuế, Báo cáo về nợ thuế, Báo cáo về hoàn thuế, Báo cáo về miễn giảm thuế, Báo cáo về kiểm tra thuế (khai thác tại TMS) | G9: Kê khai thuế, Nợ thuế, Hoàn thuế, Miễn giảm thuế, Kiểm tra thuế | H9: Cơ quan thuế tỉnh | I9: 1 | J9: 3, 4 | K9: Khai thác phục vụ công tác chuẩn bị kiểm toán, thực hiện kiểm toán các cuộc kiểm toán ngân sách địa phương, báo cáo ngân sách địa phương, chuyên đề có liên quan | L9: Thường xuyên
A10: 2 | B10: NS-09 | C10: 2 , 3 | D10: A1, A2 | E10: Chấp hành ngân sách nhà nước, Quyết toán ngân sách nhà nước | F10: Báo cáo về hoá đơn, tình hình sử dụng hoá đơn. Khai thác hoá đơn điện tử (hddtcbt.gdt.gov.vn) | G10: Tra soát hoá đơn để thực hiện kiểm toán các công tác kiểm tra thuế, kê khai thuế. | H10: Cơ quan thuế tỉnh | I10: 1 | J10: 3, 4 | K10: Khai thác phục vụ công tác chuẩn bị kiểm toán, thực hiện kiểm toán các cuộc kiểm toán ngân sách địa phương, báo cáo ngân sách địa phương, chuyên đề có liên quan | L10: Thường xuyên
A11: 3 | B11: NS-04 | C11: 2 , 3 | D11: A1, A2 | E11: Chấp hành ngân sách nhà nước, Quyết toán ngân sách nhà nước | F11: Thông tin báo cáo tài chính, tờ khai thuế, tờ khai và hồ sơ hoàn thuế (dichvucongcbt.gdt.gov.vn) | G11: Tra cứu báo cáo tài chính, tờ khai thuế, tờ khai và hồ sơ hoàn thuế | H11: Cơ quan thuế tỉnh | I11: 1 | J11: 3, 4 | K11: Khai thác phục vụ công tác chuẩn bị kiểm toán, thực hiện kiểm toán các cuộc kiểm toán ngân sách địa phương, báo cáo ngân sách địa phương, chuyên đề có liên quan | L11: Thường xuyên
A12: 4 | B12: NS-04 | C12: 2 , 3 | D12: A1, A2 | E12: Chấp hành ngân sách nhà nước, Quyết toán ngân sách nhà nước | F12: Thông tin về tính hình kiểm tra thuế, báo cáo rủi ro về thuế (Ứng dụng TPR và hệ thống quản lý rủi ro) | G12: Thực hiện kiểm toán kiểm tra thuế, quản lý doanh nghiệp | H12: Cơ quan thuế tỉnh | I12: 1 | J12: 3, 4 | K12: Khai thác phục vụ công tác chuẩn bị kiểm toán, thực hiện kiểm toán các cuộc kiểm toán ngân sách địa phương, báo cáo ngân sách địa phương, chuyên đề có liên quan | L12: Thường xuyên
A13: 5 | B13: NS-04 | C13: 2 , 3 | D13: A1, A2 | E13: Chấp hành ngân sách nhà nước, Quyết toán ngân sách nhà nước | F13: Thông tin để phân tích dữ liệu giao dịch liên kết, lọc dữ liệu từ Orbis và tính toán các chỉ ⭢tiêu tài chính (như tỷ suất lợi nhuận, khoảng tứ phân vị) nhằm so sánh với người nộp thuế) (Ứng dụng TP Catalyst) | G13: Thực hiện kiểm tra hồ sơ chuyển giá, hồ sơ ấn định thuế | H13: Cơ quan thuế tỉnh | I13: 1 | J13: 3, 4 | K13: Khai thác phục vụ công tác chuẩn bị kiểm toán, thực hiện kiểm toán các cuộc kiểm toán ngân sách địa phương, báo cáo ngân sách địa phương, chuyên đề có liên quan | L13: Thường xuyên
A14: 6 | B14: NS-04 | C14: 2 , 3 | D14: A1, A2 | E14: Chấp hành ngân sách nhà nước, Quyết toán ngân sách nhà nước | F14: Thông tin cơ sở dữ liệu tài chính và thương mại toàn cầu chứa thông tin của hàng triệu doanh nghiệp trên thế giới và tại Việt Nam (Cơ quan thuế dùng dữ liệu này để tìm kiếm các công ty so sánh độc lập (Orbis)) | G14: Thực hiện kiểm tra hồ sơ chuyển giá, hồ sơ ấn định thuế | H14: Cơ quan thuế tỉnh | I14: 1 | J14: 3, 4 | K14: Khai thác phục vụ công tác chuẩn bị kiểm toán, thực hiện kiểm toán các cuộc kiểm toán ngân sách địa phương, báo cáo ngân sách địa phương, chuyên đề có liên quan | L14: Thường xuyên
A15: 7 | B15: NS-09 | C15: 2 , 3 | D15: A1, A2 | E15: Chấp hành ngân sách nhà nước, Quyết toán ngân sách nhà nước | F15: Thông tin hoá đơn có rủi ro về thuế. (thongtincanhbao.hcm.tct.vn) | G15: Tra soát hoá đơn để thực hiện kiểm toán các công tác kiểm tra thuế, kê khai thuế. | H15: Cơ quan thuế tỉnh (đây là phần mềm riêng của thuế thành phố Hồ Chí Minh, nhưng có thể cấp phát để sử dụng cho các khu vực) | I15: 1 | J15: 3, 4, 5 | K15: Khai thác phục vụ công tác chuẩn bị kiểm toán, thực hiện kiểm toán các cuộc kiểm toán ngân sách địa phương, báo cáo ngân sách địa phương, chuyên đề có liên quan | L15: Thường xuyên
A16: 8 | B16: NS-04 | C16: 2 , 3 | D16: A1, A2 | E16: Chấp hành ngân sách nhà nước, Quyết toán ngân sách nhà nước | F16: Thông tin các báo cáo của cơ quan thuế (csdlnnt.gdt.gov.vn) | G16: Tra cứu các báo cáo của cơ quan thuế (ứng dứng cơ sở dữ liệu) | H16: Cơ quan thuế tỉnh | I16: 1 | J16: 3, 4 | K16: Khai thác phục vụ công tác chuẩn bị kiểm toán, thực hiện kiểm toán các cuộc kiểm toán ngân sách địa phương, báo cáo ngân sách địa phương, chuyên đề có liên quan | L16: Thường xuyên
A17: 9 | B17: NS-02, NS-06 | C17: 2.3 | D17: A1, A2 | E17: Chấp hành ngân sách nhà nước, Quyết toán ngân sách nhà nước | F17: Báo cáo B2-01/BC-NS/TABMIS, B2-02/BC-NS/TABMIS: Báo cáo thu và vay của NSNN niên độ… | G17: Tổng mức dự toán; dự toán chi tiết theo lĩnh vực thu, theo mục lục ngân sách | H17: Kho bạc nhà nước | I17: 2 | J17: 3, 4 | K17: Đối chiếu thưc hiện thu NSNN của cơ quan tài chính với KBNN | L17: Thường xuyên
F18: Báo cáo B2-03/BC-NS/TABMIS: Báo cáo tổng hợp thu NSNN theo sắc thuế niên độ…
F19: Báo cáo B2-04/BC-NS/TABMIS: Báo cáo thu NSNN ngành Hải quan niên độ…
F20: Báo cáo B2-05/BC-NS/TABMIS: Báo cáo hoàn trả thu NSNN niên độ …
A21: 10 | B21: NS-02, NS-06 | C21: 2.3 | D21: A1, A2 | E21: Chấp hành ngân sách nhà nước, Quyết toán ngân sách nhà nước | F21: Báo cáo B3-01/BC-NS/TABMIS: Báo cáo chi và trả nợ vay NSNN, niên độ.. | G21: Tổng mức dự toán; dự toán chi tiết theo lĩnh vực chi , theo mục lục ngân sách | H21: Kho bạc nhà nước | I21: 2 | J21: 3, 4 | K21: Đối chiếu thưc hiện chi NSNN, chi NSĐP của cơ quan tài chính với KBNN | L21: Thường xuyên
F22: Báo cáo B3-02/BC-NS/TABMIS: Báo cáo chi và trả nợ vay NSĐP, niên độ ...
F23: Báo cáo B3-03/BC-NS/TABMIS: Báo cáo chi và trả nợ vay NSNN theo MLNSNN niên độ…
F24: Báo cáo B3-04/BC-NS/TABMIS: Báo cáo thực hiện chi và trả nợ NSTW, niên độ…
F25: Báo cáo B3-04a/BC-NS/TABMIS: Báo cáo thực hiện chi đầu tư XDCB NSTW, niên độ …
F26: Báo cáo B3-04b/BC-NS/TABMIS: Báo cáo thực hiện chi thường xuyên NSTW, niên độ …
F27: Báo cáo B3-05/BC-NS/TABMIS: Báo cáo thực hiện chi, trả nợ ngân sách (cấp tỉnh/ cấp huyện/ cấp xã) niên độ…
F28: Báo cáo B3-05a/BC-NS/TABMIS: Báo cáo thực hiện chi đầu tư XDCB ngân sách (cấp tỉnh/ cấp xã) niên độ…
F29: Báo cáo B3-05b/BC-NS/TABMIS: Báo cáo thực hiện chi thường xuyên ngân sách (cấp tỉnh/ cấp xã) niên độ…
A30: 11 | B30: NS-02, NS-06 | C30: 2.3 | D30: A1, A2 | E30: Chấp hành ngân sách nhà nước, Quyết toán ngân sách nhà nước | F30: Báo cáo B4-01/BC-NS/TABMIS: Chi các chương trình, mục tiêu và dự án quốc gia, niên độ... | G30: Tổng mức dự toán; dự toán chi tiết theo lĩnh vực chi, theo mục lục ngân sách | H30: Kho bạc nhà nước | I30: 2 | J30: 3, 4 | K30: Đối chiếu thưc hiện chi NSNN, chi NSĐP của cơ quan tài chính với KBNN về chương trình mục tiêu quốc gia | L30: Thường xuyên
F31: Báo cáo B4-02/BC-NS/TABMIS: Chi các chương trình, mục tiêu và dự án quốc gia theo mục lục NSNN niên độ…
A32: 12 | B32: NS-02, NS-03 | C32: 2.3 | D32: A1, A2 | E32: Dự toán NSNN, Chấp hành NSNN | F32: Báo cáo B5-01/BC-NS/TABMIS: Tình hình sử dụng dự toán chi Đầu tư phát triển NSTW (cấp tỉnh/cấp xã) theo hình thức rút dự toán niên độ… | G32: Tổng mức dự toán; dự toán chi tiết theo đơn vị dự toán, theo lĩnh vực chi, theo mục lục ngân sách; số điều chỉnh, bổ sung | H32: Kho bạc nhà nước | I32: 2 | J32: 3, 4 | K32: Đối chiếu chi đầu tư bằng hình thức dự toán cơ quan tài chính giao với số liệu nhập Tabmis; đối chiếu số dự toán được giao, số rút dự toán, số kinh phí chuyển sang năm sau của với số liệu KBNN | L32: Thường xuyên
C33: 2.3 | D33: A1, A2 | E33: Dự toán NSNN, Chấp hành NSNN | F33: Báo cáo B5-02/BC-NS/TABMIS: Tình hình sử dụng dự toán chi đầu tư phát triển NSTW (cấp tỉnh/cấp xã) theo hình thức lệnh chi tiền, niên độ… | G33: Tổng mức dự toán; dự toán chi tiết theo đơn vị dự toán, theo lĩnh vực chi, theo mục lục ngân sách; số điều chỉnh, bổ sung | H33: Kho bạc nhà nước | I33: 2 | J33: 3, 4 | K33: Đối chiếu chi đầu tư bằng lệnh chi tiền của cơ quan tài chính giao với số liệu nhập Tabmis; đối chiếu số dự toán được giao, số rút dự toán, số kinh phí chuyển sang năm sau của với số liệu KBNN | L33: Thường xuyên
C35: 2.3 | D35: A1, A2 | E35: Dự toán NSNN, Chấp hành NSNN | F35: Báo cáo B5-03/BC-NS/TABMIS: Tình hình sử dụng dự toán chi thường xuyên NSTW (cấp tỉnh/cấp xã) theo hình thức rút dự toán, niên độ… | G35: Tổng mức dự toán; dự toán chi tiết theo đơn vị dự toán, theo lĩnh vực chi, theo mục lục ngân sách; số điều chỉnh, bổ sung | H35: Kho bạc nhà nước | I35: 2 | J35: 3, 4 | K35: Đối chiếu dự toán cơ quan tài chính giao với số liệu nhập Tabmis; đối chiếu số dự toán được giao, số rút dự toán, số kinh phí chuyển sang năm sau của đơn vị dự toán với số liệu KBNN; xác định các khoản điều chỉnh, bổ sung dự toán trong năm | L35: Thường xuyên
C37: 2.3 | D37: A1, A2 | E37: Dự toán NSNN, Chấp hành NSNN | F37: Báo cáo B5-04/BC-NS/TABMIS: Tình hình sử dụng dự toán chi thường xuyên NSTW (cấp tỉnh/cấp xã) theo hình thức lệnh chi tiền, niên độ… | G37: Tổng mức dự toán; dự toán chi tiết theo đơn vị dự toán, theo lĩnh vực chi, theo mục lục ngân sách; số điều chỉnh, bổ sung | H37: Kho bạc nhà nước | I37: 2 | J37: 3, 4 | K37: Đối chiếu số kinh phí cấp bằng lệnh chi tiền của cơ quan tài chính giao với số liệu nhập Tabmis; số rút kinh phí; xác định các khoản điều chỉnh, bổ sung dự toán trong năm | L37: Thường xuyên
C39: 2.3 | D39: A1, A2 | E39: Dự toán NSNN, Chấp hành NSNN | F39: Báo cáo B5-05/BC-NS/TABMIS: Tình hình sử dụng dự toán chi bổ sung cho ngân sách cấp dưới của NSTW (cấp tỉnh) niên độ... | G39: Tổng mức dự toán; dự toán chi tiết theo đơn vị cấp dưới, theo mục lục ngân sách; số điều chỉnh, bổ sung | H39: Kho bạc nhà nước | I39: 2 | J39: 3, 4 | K39: Đối chiếu số kinh phí cấp bằng lệnh chi tiền của cơ quan tài chính giao với số liệu nhập Tabmis; số rút kinh phí; xác định các khoản điều chỉnh, bổ sung dự toán trong năm | L39: Thường xuyên
A41: 13 | B41: NS-02, NS-06 | C41: 2.3 | D41: A1, A2 | E41: Dự toán NSNN, Chấp hành NSNN | F41: - Báo cáo B5-04/BC-NS/TABMIS: Vay, trả nợ Ngân sách nhà nước niên độ.... - Báo cáo B5-05/BC-NS/TABMIS: Vay, trả nợ Ngân sách địa phương niên độ.... | G41: Tình hình và và trả nợ gốc, lãi, phí | H41: Kho bạc nhà nước | I41: 2 | J41: 3, 4 | K41: Đối chiếu Tình hình và và trả nợ gốc, lãi, phí | L41: Thường xuyên
A42: 15 | B42: NS-06 | C42: 3 | D42: A1, A4, B1 | E42: Quyết toán NSNN | F42: Báo cáo quyết toán NSĐP tỉnh đã được HĐND phê chuẩn | G42: Tổng thu, chi, bội chi theo cấp ngân sách; kết dư; chuyển nguồn | H42: Sở Tài chính | I42: 3 | J42: 02, 03 | K42: Khai thác lập KHKT thực hiện KT và lập KH trung hạn, KH KT năm để xác định quy mô, đầu mối, rủi ro khi lập kế hoạch kiểm toán; đối chiếu kết dư, chuyển nguồn giữa các năm; kiểm tra việc điều chỉnh quyết toán theo kiến nghị kiểm toán | L42: Định kỳ
A43: 16 | B43: NS-10 | C43: 2 | D43: A1, A2 | E43: Tài sản công | F43: Dữ liệu đăng ký tài sản công là nhà, đất, xe ô tô và tài sản có giá trị lớn | G43: Danh mục, nguyên giá, giá trị còn lại, hiện trạng sử dụng; tài sản dôi dư sau sắp xếp | H43: Sở Tài chính | I43: 2 | J43: 4 | K43: Khai thác phục vụ lập kế hoạch KT và thực hiện kiểm toán để đối chiếu tài sản sổ sách với thực tế; phát hiện tài sản dôi dư chưa xử lý, sử dụng sai mục đích | L43: Thường xuyên
A44: =A43+1 -> 17 | B44: NS-11 | C44: 2 | D44: A1, A2 | E44: Nợ công | F44: Dữ liệu vay, trả nợ của chính quyền địa phương | G44: Dư nợ, hạn mức vay, số vay, trả gốc, lãi trong năm | H44: Sở Tài chính | I44: 2, 3 | J44: 3, 4 | K44: Khai thác phục vụ lập kế hoạch KT và thực hiện kiểm toán để kiểm tra tuân thủ hạn mức dư nợ, bội chi; đánh giá nghĩa vụ trả nợ | L44: Định kỳ
A45: =A44+1 -> 18 | B45: NS-12 | C45: 2 | D45: A2 | E45: Biên chế, quỹ tiền lương | F45: Quyết định giao biên chế, số người làm việc; quỹ lương của đơn vị sử dụng ngân sách | G45: Biên chế giao, có mặt; quỹ lương, phụ cấp; số giải quyết chế độ nghỉ việc | H45: Sở Nội vụ; đơn vị được kiểm toán | I45: 3 | J45: 1, 3 | K45: Khai thác phục vụ thực hiện kiểm toán để đối chiếu quỹ lương chi trả với biên chế giao; kiểm tra chi giải quyết chế độ nghỉ việc | L45: Thường xuyên
...

Sheet PL02
A1: BIỂU SỐ 02
A2: NGUỒN DỮ LIỆU ĐỀ NGHỊ ƯU TIÊN KẾT NỐI, KHAI THÁC TRƯỚC
A3: (Kèm theo Công văn số /KV XII - TH ngày tháng 9 năm 2026 của KTNN khu vực XII)
A4: Đơn vị báo cáo: KTNN khu vực XII
A6: Thứ tự ưu tiên | B6: Mã nguồn | C6: Tên dữ liệu | D6: Lý do đề nghị ưu tiên
A7: 1 | B7: NS-02, 03, 06 | C7: Dữ liệu dự toán, chấp hành và quyết toán chi NSĐP | D7: Là căn cứ đối chiếu số liệu thưc hiện chi chi NSĐP của cơ quan tài chính, của đơn vị dự toán với KBNN
A8: =A7+1 -> 2 | B8: NS-06 | C8: BCQT NSĐP tỉnh | D8: Là căn cứ lập kế hoạch kiểm toán năm. Nhận bản giấy, bản scan; phải nhập lại thủ công các biểu quyết toán mỗi năm.
A9: =A8+1 -> 3 | B9: ='PL01'!B47 -> ĐT-02 | C9: ='PL01'!E47 -> Kế hoạch vốn đầu tư công | D9: Phục vụ kiểm tra bố trí, phân bổ và giải ngân vốn, nhận diện dự án bố trí vốn chưa phù hợp tiến độ, giải ngân thấp, kéo dài thời gian thực hiện hoặc phát sinh nợ đọng; hỗ trợ lựa chọn dự án có rủi ro để kiểm toán.
A10: =A9+1 -> 4 | B10: ='PL01'!B46 -> ĐT-01 | C10: ='PL01'!E46 -> Chủ trương và quyết định đầu tư | D10: Cung cấp dữ liệu nền về mục tiêu, quy mô, tổng mức đầu tư, nguồn vốn, tiến độ và các lần điều chỉnh dự án; phục vụ đánh giá tuân thủ trình tự đầu tư và nhận diện dự án điều chỉnh tổng mức đầu tư, quy mô hoặc tiến độ nhiều lần.
A11: =A10+1 -> 5 | B11: ='PL01'!B52 -> ĐT-07 | C11: ='PL01'!E52 -> Quyết toán dự án | D11: Phản ánh toàn bộ chi phí đầu tư cuối cùng của dự án, cho phép tổng hợp và đối chiếu từ tổng mức đầu tư, hợp đồng, thanh toán đến giá trị quyết toán; phục vụ phát hiện chi phí không hợp lý, vượt dự toán và xác định giá trị tài sản hình thành qua đầu tư.
A12: =A11+1 -> 6 | B12: DN-02 | C12: Báo cáo tài chính doanh nghiệp và Báo cáo kiểm toán độc lập | D12: Khối lượng doanh nghiệp nhà nước trên địa bàn hai tỉnh lớn, dữ liệu tài chính hiện chủ yếu thu thập qua hồ sơ giấy hoặc tệp rời rạc, mất nhiều thời gian tổng hợp, đối chiếu thủ công khi lập kế hoạch kiểm toán.
A13: =A12+1 -> 7 | B13: CH-02 | C13: Kết luận thanh tra, kiểm tra và kết luận kiến nghị Kiểm toán nhà nước các năm trước | D13: Các kết luận thanh tra, kiểm toán trước đây lưu trữ phân tán, khi khảo sát lập kế hoạch kiểm toán DNNN tại Đồng Nai và Lâm Đồng, kiểm toán viên mất nhiều thời gian tra cứu thủ công, dẫn đến khó đánh giá tính liên tục của sai phạm hoặc việc khắc phục kiến nghị của đơn vị. Cần số hóa và tích hợp vào kho dữ liệu dùng chung để tra cứu nhanh.
A14: =A13+1 -> 8 | B14: NS-04 | C14: Báo cáo về kê khai thuế, Báo cáo về nợ thuế, Báo cáo về hoàn thuế, Báo cáo về miễn giảm thuế, Báo cáo về kiểm tra thuế (khai thác tại TMS) | D14: Là căn cứ đối chiếu số liệu kê khai thuế, nợ thuế, hoàn thuế, miễn giảm thuế, kiểm tra thuế . Hiện phải đề nghị cung cấp theo từng cuộc, thời gian chờ dài, số liệu không thống nhất giữa các lần cung cấp.
A15: =A14+1 -> 9 | B15: NS-04 | C15: Báo cáo về hoá đơn, tình hình sử dụng hoá đơn. Khai thác hoá đơn điện tử (hddtcbt.gdt.gov.vn) | D15: Là căn cứ Tra soát hoá đơn để thực hiện kiểm toán các công tác kiểm tra thuế, kê khai thuế. Hiện phải đề nghị cung cấp theo từng cuộc, thời gian chờ dài, số liệu không thống nhất giữa các lần cung cấp.
A16: =A15+1 -> 10 | B16: NS-04 | C16: Thông tin báo cáo tài chính, tờ khai thuế, tờ khai và hồ sơ hoàn thuế (dichvucongcbt.gdt.gov.vn) | D16: Là căn cứ tra cứu báo cáo tài chính, tờ khai thuế, tờ khai và hồ sơ hoàn thuế. Hiện phải đề nghị cung cấp theo từng cuộc, thời gian chờ dài, số liệu không thống nhất giữa các lần cung cấp.
A17: =A16+1 -> 11 | B17: ='PL01'!B50 -> ĐT-05 | C17: ='PL01'!E50 -> Hợp đồng | D17: Là căn cứ xác định phạm vi công việc, giá hợp đồng, loại hợp đồng, tiến độ và điều kiện thanh toán; cần thiết để kiểm tra việc thực hiện hợp đồng, điều chỉnh giá, phát sinh khối lượng, gia hạn và nghiệm thu, thanh toán.
A18: =A17+1 -> 12 | B18: ='PL01'!B51 -> ĐT-06 | C18: ='PL01'!E51 -> Nghiệm thu, thanh toán | D18: Dữ liệu trực tiếp phản ánh khối lượng và giá trị đã nghiệm thu, thanh toán từ nguồn vốn nhà nước; có thể phân tích, đối chiếu với hợp đồng, dự toán, thiết kế và quyết toán để phát hiện thanh toán sai khối lượng, đơn giá, thanh toán vượt hợp đồng, trùng lặp hoặc không đúng thực tế
A19: =A18+1 -> 13 | B19: ='PL01'!B48 -> ĐT-03 | C19: ='PL01'!E48 -> Thiết kế, dự toán | D19: Là cơ sở xác định khối lượng, định mức, đơn giá và giá trị được phê duyệt, phục vụ kiểm tra tính đúng đắn của dự toán và đối chiếu với hồ sơ mời thầu, hợp đồng, nghiệm thu, thanh toán; có ảnh hưởng trực tiếp đến giá gói thầu và chi phí đầu tư.
A20: =A19+1 -> 14 | B20: ='PL01'!B49 -> ĐT-04 | C20: ='PL01'!E49 -> Lựa chọn nhà thầu | D20: Phục vụ phân tích giá gói thầu, giá dự thầu, giá trúng thầu, tỷ lệ tiết kiệm, nhà thầu tham dự/trúng thầu, hình thức lựa chọn nhà thầu; hỗ trợ nhận diện dấu hiệu hạn chế cạnh tranh, tỷ lệ tiết kiệm thấp, nhà thầu trúng thầu lặp lại và các bất thường trong đấu thầu.
A21: =A20+1 -> 15 | B21: ='PL01'!B53 -> ĐT-08 | C21: ='PL01'!E53 -> Định mức, đơn giá | D21: Là dữ liệu tham chiếu quan trọng để kiểm tra dự toán, giá gói thầu, điều chỉnh giá và thanh toán, hỗ trợ tự động hóa việc xác định trường hợp áp dụng sai định mức, đơn giá hoặc giá vật liệu bất hợp lý.
A22: =A21+1 -> 16 | B22: NS-04 | C22: Thông tin về tính hình kiểm tra thuế, báo cáo rủi ro về thuế (Ứng dụng TPR và hệ thống quản lý rủi ro) | D22: Là căn cứ thực hiện kiểm toán kiểm tra thuế, quản lý doanh nghiệp. Hiện phải đề nghị cung cấp theo từng cuộc, thời gian chờ dài, số liệu không thống nhất giữa các lần cung cấp.
A23: =A22+1 -> 17 | B23: NS-09 | C23: Hóa đơn điện tử | D23: Hiện tra cứu từng hóa đơn thủ công; không kiểm tra được toàn bộ hóa đơn trong hồ sơ thanh toán.
A24: =A23+1 -> 18 | B24: NS-04 | C24: Thông tin để phân tích dữ liệu giao dịch liên kết, lọc dữ liệu từ Orbis và tính toán các chỉ ⭢tiêu tài chính (như tỷ suất lợi nhuận, khoảng tứ phân vị) nhằm so sánh với người nộp thuế) (Ứng dụng TP Catalyst) | D24: Là căn cứ thực hiện kiểm tra hồ sơ chuyển giá, hồ sơ ấn định thuế. Hiện phải đề nghị cung cấp theo từng cuộc, thời gian chờ dài, số liệu không thống nhất giữa các lần cung cấp.
A25: =A24+1 -> 19 | B25: NS-04 | C25: Thông tin cơ sở dữ liệu tài chính và thương mại toàn cầu chứa thông tin của hàng triệu doanh nghiệp trên thế giới và tại Việt Nam (Cơ quan thuế dùng dữ liệu này để tìm kiếm các công ty so sánh độc lập (Orbis)) | D25: Là căn cứ thực hiện kiểm tra hồ sơ chuyển giá, hồ sơ ấn định thuế. Hiện phải đề nghị cung cấp theo từng cuộc, thời gian chờ dài, số liệu không thống nhất giữa các lần cung cấp.
A26: =A25+1 -> 20 | B26: NS-04 | C26: Thông tin hoá đơn có rủi ro về thuế. (thongtincanhbao.hcm.tct.vn) | D26: Là căn cứ tra soát hoá đơn để thực hiện kiểm toán các công tác kiểm tra thuế, kê khai thuế.. Hiện phải đề nghị cung cấp theo từng cuộc, thời gian chờ dài, số liệu không thống nhất giữa các lần cung cấp.
A27: =A26+1 -> 21 | B27: NS-04 | C27: Thông tin các báo cáo của cơ quan thuế (csdlnnt.gdt.gov.vn) | D27: Là căn cứ tra cứu các báo cáo của cơ quan thuế (ứng dứng cơ sở dữ liệu). Hiện phải đề nghị cung cấp theo từng cuộc, thời gian chờ dài, số liệu không thống nhất giữa các lần cung cấp.
A28: =A27+1 -> 22 | B28: ='PL01'!B54 -> ĐT-09 | C28: ='PL01'!E54 -> Đất đai, giải phóng mặt bằng | D28: Phục vụ kiểm toán thu hồi đất, bồi thường, hỗ trợ, tái định cư và chi phí GPMB; có giá trị cao đối với dự án có chi phí GPMB lớn nhưng phạm vi áp dụng hẹp hơn các nhóm dữ liệu chung nêu trên.
A29: =A28+1 -> 23 | B29: CĐ-03 | C29: Giao đất, cho thuê đất, giá đất | D29: Thu tiền sử dụng đất chiếm tỷ trọng lớn trong thu NSĐP. Dữ liệu ở bản giấy, phân tán; không đối chiếu được số phải thu với số đã thu nên dễ bỏ sót chậm xác định giá đất, thất thu.
A30: =A29+1 -> 24 | B30: NS-10 | C30: Tài sản công | D30: Sau sắp xếp đơn vị hành chính phát sinh nhiều tài sản dôi dư. Không có dữ liệu thì không xác định được tài sản chưa xử lý, sử dụng sai mục đích.
A31: =A30+1 -> 25 | B31: ='PL01'!B55 -> ĐT-10 | C31: ='PL01'!E55 -> Bản đồ, hiện trạng công trình | D31: Hữu ích trong việc đối chiếu vị trí, diện tích, quy mô và hiện trạng thực tế với hồ sơ thiết kế, nghiệm thu, hỗ trợ kiểm tra khối lượng; tuy nhiên việc chuẩn hóa, liên thông và khai thác tự động thường phức tạp hơn dữ liệu dạng số, bảng biểu.
A32: =A31+1 -> 26 | B32: CĐ-02 | C32: CTMTQG | D32: Số lượng đối tượng lớn, phân tán tại cấp xã; kiểm tra thủ công chỉ chọn được mẫu nhỏ, không phát hiện được chi trùng, sai đối tượng.
A33: =A32+1 -> 27 | B33: BS-01 | C33: Hồ sơ bàn giao khi sắp xếp đơn vị hành chính | D33: Chỉ tồn tại ở bản giấy tại nhiều đơn vị; nếu không số hóa sớm, nguy cơ thất lạc, không truy nguyên được số dư tạm ứng, công nợ của cấp huyện cũ.
A34: =A33+1 -> 28 | B34: NS-12 | C34: Biên chế, quỹ tiền lương | D34: Kinh phí giải quyết chế độ nghỉ việc lớn trong giai đoạn tinh gọn bộ máy; thiếu dữ liệu thì không đối chiếu được đối tượng, số tiền chi trả.
